version: '3.7'

networks:
  central-de-ajuda-network:
    driver: bridge

services:

  phpmyadmin:
    depends_on:
      - db_local_dev_central_de_ajuda
    image: phpmyadmin/phpmyadmin
    restart: always
    ports:
      - 8082:80
    environment:
      PMA_HOST: db_local_dev_central_de_ajuda
      MYSQL_ROOT_PASSWORD: 1
    networks:
      - central-de-ajuda-network

  db_local_dev_central_de_ajuda:
    tty: true
    restart: on-failure
    networks:
      - central-de-ajuda-network
    healthcheck:
      test: ["CMD-SHELL", "mysqladmin ping -h localhost"]
      interval: 30s
      timeout: 10s
      retries: 5
    image: mysql:8
    volumes:
      - ./mysql-local:/var/lib/mysql
    ports: 
      - 3307:3307
    environment:
      - DATABASE_USER=root
      - MYSQL_USER=admin
      - MYSQL_PASSWORD=admin
      - MYSQL_ROOT_PASSWORD=root
      - MYSQL_DATABASE=db_local_dev_central_de_ajuda
    command: --default-authentication-plugin=mysql_native_password --innodb-use-native-aio=0

  central_de_ajuda_dev:
    networks:
      - central-de-ajuda-network
    container_name: central_de_ajuda_dev
    restart: always
    depends_on:
      - db_local_dev_central_de_ajuda
    volumes: 
      - .:/central-de-ajuda-rs/
    build:
      context: .
      dockerfile: Dockerfile
    ports:
      - "8000:8000"
    environment:
      - DEBUG=True
      - PYTHONUNBUFFERED=1

      - APP_DATABASE_NAME=db_local_dev_central_de_ajuda
      - APP_DATABASE_USER=root  
      - APP_DATABASE_PASSWORD=root
      - APP_DATABASE_PORT=3306
      - APP_DATABASE_HOST=db_local_dev_central_de_ajuda

    command: python manage.py runserver 0.0.0.0:8000